<?xml version="1.0"?>
<robot name="underwater">

    <!-- * * * Color Definitions * * * -->

    <material name="white">
        <color rgba="1 1 1 1"/>
    </material>

    <material name="green2">
        <color rgba="0.8 0.9 0.8 0.9"/>
    </material> 

    <material name="red">
        <color rgba="0.8 0 0 1"/>
    </material>

    <material name="gray">
        <color rgba="0.5 0.5 0.5 0.9"/>
    </material>

    <material name="transparent">
        <color rgba="1 1 1 0.4"/>
    </material>

    <material name="full_transparent">
        <color rgba="1 1 1 0"/>
    </material>

    <!-- * * * Link Definitions * * * -->

    <!-- mesh files -->
    <link name="robot_base_link">
        <inertial>
            <origin xyz="0 0 0" rpy="0 0 0"/>
            <mass value="0.607" />
            <inertia ixx="0.0002835" ixy="0.0" ixz="0.0" iyy="0.0002835" iyz="0.0" izz="0.000324"/>
        </inertial>

        <collision>
            <origin xyz="0 0 0" rpy="0 0 0"/>
            <geometry>
                <cylinder radius="0.6" length="0.09"/>
            </geometry>
        </collision>

        <visual>
            <origin rpy="0 0 0" xyz="0 0 -0.2"/>
            <geometry>
                <mesh filename="package://underwater_sim/models/meshes/robot/MainBody.dae" scale="0.0025 0.0025 0.0025"/>
            </geometry>
            <material name="white"/>
        </visual>
    </link> 

    <link name="center_link">
        <visual>
            <origin rpy="0 0 0" xyz="-0.076 -0.080 -0.035"/>
            <geometry>
                <mesh filename="package://underwater_sim/models/meshes/robot/CentralPropeller.dae" scale="0.0025 0.0025 0.0025"/>
            </geometry>
            <material name="black"/>
        </visual>
    </link> 


    <link name="shaft1_link">
        <!--
        <inertial>
            <origin rpy="0 0 3.1415" xyz="0 0 -0.085"/>
            <mass value="0.18" />
            <inertia ixx="0.0002835" ixy="0.0" ixz="0.0" iyy="0.0002835" iyz="0.0" izz="0.000324"/>
        </inertial>
        !-->
        <visual>
            <origin rpy="0 0 3.1415" xyz="0 0 -0.085"/>
            <geometry>
                <mesh filename="package://underwater_sim/models/meshes/robot/Shaft.dae" scale="0.0025 0.0025 0.0025"/>
            </geometry>
            <material name="white"/>
        </visual>
    </link> 

    <link name="shaft2_link">
        <!--
        <inertial>
            <origin rpy="3.1415 0 0" xyz="0 0 0.085"/>
            <mass value="0.18" />
            <inertia ixx="0.0002835" ixy="0.0" ixz="0.0" iyy="0.0002835" iyz="0.0" izz="0.000324"/>
        </inertial>
        !-->
        <visual>
            <origin rpy="3.1415 0 0" xyz="0 0 0.085"/>
            <geometry>
                <mesh filename="package://underwater_sim/models/meshes/robot/Shaft.dae" scale="0.0025 0.0025 0.0025"/>
            </geometry>
            <material name="white"/>
        </visual>
    </link>  

    <link name="shaft3_link">
        <!--
        <inertial>
            <origin rpy="0 0 3.1415" xyz="0 0 -0.085"/>
            <mass value="0.18" />
            <inertia ixx="0.0002835" ixy="0.0" ixz="0.0" iyy="0.0002835" iyz="0.0" izz="0.000324"/>
        </inertial>
        !-->
        <visual>
            <origin rpy="0 0 3.1415" xyz="0 0 -0.085"/>
            <geometry>
                <mesh filename="package://underwater_sim/models/meshes/robot/Shaft.dae" scale="0.0025 0.0025 0.0025"/>
            </geometry>
            <material name="white"/>
        </visual>
    </link> 

    <link name="cylinder1_link">


        <visual>
            <origin rpy="0 0 3.1415" xyz="0.26 .15 0.01"/>
            <geometry>
                <mesh filename="package://underwater_sim/models/meshes/robot/Cylinder.dae" scale="0.0025 0.0025 0.0025"/>
            </geometry>
            <material name="transparent"/>
        </visual>
    </link> 

    <link name="cylinder2_link">

        <visual>
            <origin rpy="0 0 3.1415" xyz="-0.26 .15 0.01"/>
            <geometry>
                <mesh filename="package://underwater_sim/models/meshes/robot/Cylinder.dae" scale="0.0025 0.0025 0.0025"/>
            </geometry>
            <material name="transparent"/>
        </visual>
    </link>

    <link name="cylinder3_link">

        <visual>
            <origin rpy="0 0 3.1415" xyz="0 -0.3 0.01"/>
            <geometry>
                <mesh filename="package://underwater_sim/models/meshes/robot/Cylinder.dae" scale="0.0025 0.0025 0.0025"/>
            </geometry>
            <material name="transparent"/>
        </visual>
    </link> 

    <link name="motorcylinder1_link">

        <visual>
            <origin rpy="0 0 3.1415" xyz="0 0.19 0.045"/>
            <geometry>
                <mesh filename="package://underwater_sim/models/meshes/robot/TubeMotor.dae" scale="0.0025 0.0025 0.0025"/>
            </geometry>
            <material name="transparent"/>
        </visual>
    </link> 

    <link name="motorcylinder2_link">

        <visual>
            <origin rpy="0 0 1.0471975512" xyz="0.16 -0.095 0.045"/>
            <geometry>
                <mesh filename="package://underwater_sim/models/meshes/robot/TubeMotor.dae" scale="0.0025 0.0025 0.0025"/>
            </geometry>
            <material name="transparent"/>
        </visual>
    </link> 

    <link name="motorcylinder3_link">

        <visual>
            <origin rpy="0 0 2.094395" xyz="-0.53 -0.3 0.045"/>
            <geometry>
                <mesh filename="package://underwater_sim/models/meshes/robot/TubeMotor.dae" scale="0.0025 0.0025 0.0025"/>
            </geometry>
            <material name="transparent"/>
        </visual>
    </link> 

    <!-- naive geometry-->
    <!-- 
    <link name="base_link">
        <inertial>
            <origin xyz="0 0 0" rpy="0 0 0"/>
            <mass value="0.607" />
            <inertia ixx="0.0002835" ixy="0.0" ixz="0.0" iyy="0.0002835" iyz="0.0" izz="0.000324"/>
        </inertial>

        <collision>
            <origin xyz="0 0 0" rpy="0 0 0"/>
            <geometry>
                <cylinder radius="0.44056" length="0.006"/>
            </geometry>
        </collision>

        <visual>
            <origin rpy="0 0 0" xyz="0 0 0"/>
            <geometry>
                <cylinder radius="0.44056" length="0.006"/>
            </geometry>
            <material name="white"/>
        </visual>
    </link> 

    <link name="center_link">
        <inertial>
            <origin xyz="0 0 0" rpy="0 0 0"/>
            <mass value="0.210" />
            <inertia ixx="0.0002835" ixy="0.0" ixz="0.0" iyy="0.0002835" iyz="0.0" izz="0.000324"/>
        </inertial>

        <visual>
            <origin xyz="0 0 0" rpy="0 0 0"/>
            <geometry>
                <cylinder radius="0.03" length="0.06"/>
            </geometry>
            <material name="black"/>
        </visual>
    </link> 

    <link name="shaft1_link">
        <inertial>
            <origin rpy="0 0 0" xyz="0 .3464 .0"/>
            <mass value="0.18" />
            <inertia ixx="0.0002835" ixy="0.0" ixz="0.0" iyy="0.0002835" iyz="0.0" izz="0.000324"/>
        </inertial>

        <collision>
            <origin rpy="1.5708 0 0" xyz="0 .3464 .0"/>
            <geometry>
                <cylinder radius="0.05" length="0.4"/>
            </geometry>
        </collision>

        <visual>
            <origin rpy="1.5708 0 0" xyz="0 .3464 .0"/>
            <geometry>
                <cylinder radius="0.05" length="0.4"/>
            </geometry>
            <material name="white"/>
        </visual>
    </link> 

    <link name="shaft2_link">
        <inertial>
            <origin xyz="0 0 0" rpy="0 0 0"/>
            <mass value="0.18" />
            <inertia ixx="0.0002835" ixy="0.0" ixz="0.0" iyy="0.0002835" iyz="0.0" izz="0.000324"/>
        </inertial>

        <collision>
            <origin rpy="1.5708 0 0" xyz="0 .3464 0"/>
            <geometry>
                <cylinder radius="0.05" length="0.4"/>
            </geometry>
        </collision>

        <visual>
            <origin rpy="1.5708 0 0" xyz="0 .3464 0"/>
            <geometry>
                <cylinder radius="0.05" length="0.4"/>
            </geometry>
            <material name="white"/>
        </visual>
    </link>  


    <link name="shaft3_link">
        <inertial>
            <origin rpy="0 0 1.5078" xyz="0 .3464 .0"/>
            <mass value="0.18" />
            <inertia ixx="0.0002835" ixy="0.0" ixz="0.0" iyy="0.0002835" iyz="0.0" izz="0.000324"/>
        </inertial>

        <collision>
            <origin rpy="1.5078 0 0" xyz="0 .3464 .0"/>
            <geometry>
                <cylinder radius="0.02" length="0.4"/>
            </geometry>
        </collision>

        <visual>
            <origin rpy="1.5078 0 0" xyz="0 .3464 .0"/>
            <geometry>
                <cylinder radius="0.05" length="0.4"/>
            </geometry>
            <material name="white"/>
        </visual>
    </link> 
    -->

    <link name="wheel1_link">
        <inertial>
            <origin xyz="0 0 0" rpy="0 0 0"/>
            <mass value="0.361" />
            <inertia ixx="0.0002835" ixy="0.0" ixz="0.0" iyy="0.0002835" iyz="0.0" izz="0.000324"/>
        </inertial>
        <collision>
            <origin rpy="1.5708 0 0" xyz="0 0 0"/>
            <geometry>
                <cylinder radius="0.2" length="0.06"/>
            </geometry>
        </collision>
    </link>

    <link name="wheel2_link">
        <inertial>
            <origin xyz="0 0 0" rpy="0 0 0"/>
            <mass value="0.361" />
            <inertia ixx="0.0002835" ixy="0.0" ixz="0.0" iyy="0.0002835" iyz="0.0" izz="0.000324"/>
        </inertial>
        <collision>
            <origin rpy="1.5708 0 0" xyz="0 0 0"/>
            <geometry>
                <cylinder radius="0.2" length="0.06"/>
            </geometry>
        </collision>
    </link>


    <link name="wheel3_link">
        <inertial>
            <origin xyz="0 0 0" rpy="0 .54 0"/>
            <mass value="0.361" />
            <inertia ixx="0.0002835" ixy="0.0" ixz="0.0" iyy="0.0002835" iyz="0.0" izz="0.000324"/>
        </inertial>
        <collision>
            <origin rpy="1.5708 0 0" xyz="0 0 0"/>
            <geometry>
                <cylinder radius="0.2" length="0.06"/>
            </geometry>
        </collision>
    </link> 
    
    <!-- * * * Joint Definitions * * * -->

    <joint name="center_motor" type="continuous">
        <parent link="robot_base_link"/>
        <child link="center_link"/>
        <origin xyz="0.000 0 0.0005" rpy="0 0 0"/>
        <limit lower="-1" upper="1" effort="0.0" velocity="0.00"/>
        <axis xyz="0 0 1"/>
    </joint>

    <joint name="motor1" type="continuous">
        <parent link="robot_base_link"/>
        <child link="shaft1_link"/>
        <origin xyz="0 0.36 0.045" rpy="0 0 0"/>
        <limit lower="-1" upper="1" effort="0.0" velocity="0.00"/>
        <axis xyz="0 1.5708 0"/>
    </joint>  

    <joint name="motor2" type="continuous">
        <parent link="robot_base_link"/>
        <child link="shaft2_link"/>
        <origin xyz="-0.31184 -0.17988 0.045" rpy="0 0 2.094"/>
        <limit lower="-1" upper="1" effort="0.0" velocity="0.00"/>
        <axis xyz="0 1 0 "/>
    </joint> 
  
    <joint name="motor3" type="continuous">
        <parent link="robot_base_link"/>
        <child link="shaft3_link"/>
        <origin xyz="0.31184 -0.17988 0.045" rpy="0 0 -2.094"/>
        <limit lower="-1" upper="1" effort="0.0" velocity="0.00"/>
        <axis xyz="0 1 0"/>
    </joint>  

    <joint name="wheel1_joint" type="fixed">
        <parent link="shaft1_link"/>
        <child link="wheel1_link"/>
        <origin xyz="0 .50 0" rpy="0 0 0"/>
        <limit lower="-1" upper="1" effort="0.0" velocity="0.00"/>
        <axis xyz="0 1 0"/>
   </joint>

         
    <joint name="wheel2_joint" type="fixed">
        <parent link="shaft2_link"/>
        <child link="wheel2_link"/>
        <origin xyz="0 .50 0" rpy="0 0 0"/>
        <limit lower="-1" upper="1" effort="0.0" velocity="0.00"/>
        <axis xyz="0 1 0"/>
   </joint>

    <joint name="wheel3_joint" type="fixed">
        <parent link="shaft3_link"/>
        <child link="wheel3_link"/>
        <origin xyz="0 .50 0" rpy="0 0 0"/>
        <limit lower="-1" upper="1" effort="0.0" velocity="0.00"/>
        <axis xyz="0 1 0"/>
    </joint>

    <joint name="cylinder1_joint" type="fixed">
        <parent link="robot_base_link"/>
        <child link="cylinder1_link"/>
        <origin xyz="0 0 0" rpy="0 0 0"/>
        <limit lower="-1" upper="1" effort="0.0" velocity="0.00"/>
        <axis xyz="0 1 0"/>
    </joint>

    <joint name="cylinder2_joint" type="fixed">
        <parent link="robot_base_link"/>
        <child link="cylinder2_link"/>
        <origin xyz="0 0 0" rpy="0 0 0"/>
        <limit lower="-1" upper="1" effort="0.0" velocity="0.00"/>
        <axis xyz="0 1 0"/>
    </joint>

    <joint name="cylinder3_joint" type="fixed">
        <parent link="robot_base_link"/>
        <child link="cylinder3_link"/>
        <origin xyz="0 0 0" rpy="0 0 0"/>
        <limit lower="-1" upper="1" effort="0.0" velocity="0.00"/>
        <axis xyz="0 1 0"/>
    </joint>

    <joint name="motorcylinder1_joint" type="fixed">
        <parent link="robot_base_link"/>
        <child link="motorcylinder1_link"/>
        <origin xyz="0 0 0" rpy="0 0 0"/>
        <limit lower="-1" upper="1" effort="0.0" velocity="0.00"/>
        <axis xyz="0 1 0"/>
    </joint>

    <joint name="motorcylinder2_joint" type="fixed">
        <parent link="robot_base_link"/>
        <child link="motorcylinder2_link"/>
        <origin xyz="0 0 0" rpy="0 0 0"/>
        <limit lower="-1" upper="1" effort="0.0" velocity="0.00"/>
        <axis xyz="0 1 0"/>
    </joint>

    <joint name="motorcylinder3_joint" type="fixed">
        <parent link="robot_base_link"/>
        <child link="motorcylinder3_link"/>
        <origin xyz="0 0 0" rpy="0 0 0"/>
        <limit lower="-1" upper="1" effort="0.0" velocity="0.00"/>
        <axis xyz="0 1 0"/>
    </joint>

</robot> 
